[2024-02-07T16:56:16.889+0900] {taskinstance.py:1103} INFO - Dependencies all met for dep_context=non-requeueable deps ti=<TaskInstance: naver-search-pipeline.chk_api_data manual__2024-02-07T07:56:11.108114+00:00 [queued]>
[2024-02-07T16:56:16.893+0900] {taskinstance.py:1103} INFO - Dependencies all met for dep_context=requeueable deps ti=<TaskInstance: naver-search-pipeline.chk_api_data manual__2024-02-07T07:56:11.108114+00:00 [queued]>
[2024-02-07T16:56:16.893+0900] {taskinstance.py:1308} INFO - Starting attempt 1 of 1
[2024-02-07T16:56:16.903+0900] {taskinstance.py:1327} INFO - Executing <Task(PythonOperator): chk_api_data> on 2024-02-07 07:56:11.108114+00:00
[2024-02-07T16:56:16.904+0900] {standard_task_runner.py:57} INFO - Started process 177209 to run task
[2024-02-07T16:56:16.905+0900] {standard_task_runner.py:84} INFO - Running: ['airflow', 'tasks', 'run', 'naver-search-pipeline', 'chk_api_data', 'manual__2024-02-07T07:56:11.108114+00:00', '--job-id', '51', '--raw', '--subdir', 'DAGS_FOLDER/naver_search_pipeline.py', '--cfg-path', '/tmp/tmpic64v70n']
[2024-02-07T16:56:16.907+0900] {standard_task_runner.py:85} INFO - Job 51: Subtask chk_api_data
[2024-02-07T16:56:16.924+0900] {task_command.py:410} INFO - Running <TaskInstance: naver-search-pipeline.chk_api_data manual__2024-02-07T07:56:11.108114+00:00 [running]> on host localhost
[2024-02-07T16:56:16.958+0900] {taskinstance.py:1547} INFO - Exporting env vars: AIRFLOW_CTX_DAG_OWNER='airflow' AIRFLOW_CTX_DAG_ID='naver-search-pipeline' AIRFLOW_CTX_TASK_ID='chk_api_data' AIRFLOW_CTX_EXECUTION_DATE='2024-02-07T07:56:11.108114+00:00' AIRFLOW_CTX_TRY_NUMBER='1' AIRFLOW_CTX_DAG_RUN_ID='manual__2024-02-07T07:56:11.108114+00:00'
[2024-02-07T16:56:16.961+0900] {taskinstance.py:1824} ERROR - Task failed with exception
Traceback (most recent call last):
  File "/home/shan/anaconda3/envs/airflow_env/lib/python3.7/site-packages/airflow/operators/python.py", line 181, in execute
    return_value = self.execute_callable()
  File "/home/shan/anaconda3/envs/airflow_env/lib/python3.7/site-packages/airflow/operators/python.py", line 198, in execute_callable
    return self.python_callable(*self.op_args, **self.op_kwargs)
  File "/home/shan/airflow/dags/naver_search_pipeline.py", line 27, in chk_api_data
    create_event(event_data)
NameError: name 'create_event' is not defined
[2024-02-07T16:56:16.962+0900] {taskinstance.py:1350} INFO - Marking task as FAILED. dag_id=naver-search-pipeline, task_id=chk_api_data, execution_date=20240207T075611, start_date=20240207T075616, end_date=20240207T075616
[2024-02-07T16:56:16.970+0900] {standard_task_runner.py:109} ERROR - Failed to execute job 51 for task chk_api_data (name 'create_event' is not defined; 177209)
[2024-02-07T16:56:16.997+0900] {local_task_job_runner.py:225} INFO - Task exited with return code 1
[2024-02-07T16:56:17.007+0900] {taskinstance.py:2653} INFO - 0 downstream tasks scheduled from follow-on schedule check
