[2024-02-07T16:30:48.727+0900] {taskinstance.py:1103} INFO - Dependencies all met for dep_context=non-requeueable deps ti=<TaskInstance: naver-search-pipeline.chk_api_data manual__2024-02-07T07:30:43.331257+00:00 [queued]>
[2024-02-07T16:30:48.730+0900] {taskinstance.py:1103} INFO - Dependencies all met for dep_context=requeueable deps ti=<TaskInstance: naver-search-pipeline.chk_api_data manual__2024-02-07T07:30:43.331257+00:00 [queued]>
[2024-02-07T16:30:48.730+0900] {taskinstance.py:1308} INFO - Starting attempt 1 of 1
[2024-02-07T16:30:48.740+0900] {taskinstance.py:1327} INFO - Executing <Task(PythonOperator): chk_api_data> on 2024-02-07 07:30:43.331257+00:00
[2024-02-07T16:30:48.742+0900] {standard_task_runner.py:57} INFO - Started process 173427 to run task
[2024-02-07T16:30:48.743+0900] {standard_task_runner.py:84} INFO - Running: ['airflow', 'tasks', 'run', 'naver-search-pipeline', 'chk_api_data', 'manual__2024-02-07T07:30:43.331257+00:00', '--job-id', '48', '--raw', '--subdir', 'DAGS_FOLDER/naver_search_pipeline.py', '--cfg-path', '/tmp/tmp6chnya5o']
[2024-02-07T16:30:48.745+0900] {standard_task_runner.py:85} INFO - Job 48: Subtask chk_api_data
[2024-02-07T16:30:48.762+0900] {task_command.py:410} INFO - Running <TaskInstance: naver-search-pipeline.chk_api_data manual__2024-02-07T07:30:43.331257+00:00 [running]> on host localhost
[2024-02-07T16:30:48.798+0900] {taskinstance.py:1547} INFO - Exporting env vars: AIRFLOW_CTX_DAG_OWNER='airflow' AIRFLOW_CTX_DAG_ID='naver-search-pipeline' AIRFLOW_CTX_TASK_ID='chk_api_data' AIRFLOW_CTX_EXECUTION_DATE='2024-02-07T07:30:43.331257+00:00' AIRFLOW_CTX_TRY_NUMBER='1' AIRFLOW_CTX_DAG_RUN_ID='manual__2024-02-07T07:30:43.331257+00:00'
[2024-02-07T16:30:48.800+0900] {taskinstance.py:1824} ERROR - Task failed with exception
Traceback (most recent call last):
  File "/home/shan/anaconda3/envs/airflow_env/lib/python3.7/site-packages/airflow/operators/python.py", line 181, in execute
    return_value = self.execute_callable()
  File "/home/shan/anaconda3/envs/airflow_env/lib/python3.7/site-packages/airflow/operators/python.py", line 198, in execute_callable
    return self.python_callable(*self.op_args, **self.op_kwargs)
  File "/home/shan/airflow/dags/naver_search_pipeline.py", line 19, in chk_api_data
    if len(data) <= 10:
TypeError: object of type 'NoneType' has no len()
[2024-02-07T16:30:48.802+0900] {taskinstance.py:1350} INFO - Marking task as FAILED. dag_id=naver-search-pipeline, task_id=chk_api_data, execution_date=20240207T073043, start_date=20240207T073048, end_date=20240207T073048
[2024-02-07T16:30:48.810+0900] {standard_task_runner.py:109} ERROR - Failed to execute job 48 for task chk_api_data (object of type 'NoneType' has no len(); 173427)
[2024-02-07T16:30:48.835+0900] {local_task_job_runner.py:225} INFO - Task exited with return code 1
[2024-02-07T16:30:48.845+0900] {taskinstance.py:2653} INFO - 0 downstream tasks scheduled from follow-on schedule check
