[2024-02-13T10:02:54.206+0900] {taskinstance.py:1103} INFO - Dependencies all met for dep_context=non-requeueable deps ti=<TaskInstance: naver-search-pipeline.task_print_today manual__2024-02-13T01:02:49.486647+00:00 [queued]>
[2024-02-13T10:02:54.210+0900] {taskinstance.py:1103} INFO - Dependencies all met for dep_context=requeueable deps ti=<TaskInstance: naver-search-pipeline.task_print_today manual__2024-02-13T01:02:49.486647+00:00 [queued]>
[2024-02-13T10:02:54.210+0900] {taskinstance.py:1308} INFO - Starting attempt 1 of 1
[2024-02-13T10:02:54.220+0900] {taskinstance.py:1327} INFO - Executing <Task(PythonOperator): task_print_today> on 2024-02-13 01:02:49.486647+00:00
[2024-02-13T10:02:54.222+0900] {standard_task_runner.py:57} INFO - Started process 273189 to run task
[2024-02-13T10:02:54.223+0900] {standard_task_runner.py:84} INFO - Running: ['airflow', 'tasks', 'run', 'naver-search-pipeline', 'task_print_today', 'manual__2024-02-13T01:02:49.486647+00:00', '--job-id', '133', '--raw', '--subdir', 'DAGS_FOLDER/naver_search_pipeline.py', '--cfg-path', '/tmp/tmp4o3qq5zi']
[2024-02-13T10:02:54.224+0900] {standard_task_runner.py:85} INFO - Job 133: Subtask task_print_today
[2024-02-13T10:02:54.241+0900] {task_command.py:410} INFO - Running <TaskInstance: naver-search-pipeline.task_print_today manual__2024-02-13T01:02:49.486647+00:00 [running]> on host localhost
[2024-02-13T10:02:54.275+0900] {taskinstance.py:1547} INFO - Exporting env vars: AIRFLOW_CTX_DAG_OWNER='airflow' AIRFLOW_CTX_DAG_ID='naver-search-pipeline' AIRFLOW_CTX_TASK_ID='task_print_today' AIRFLOW_CTX_EXECUTION_DATE='2024-02-13T01:02:49.486647+00:00' AIRFLOW_CTX_TRY_NUMBER='1' AIRFLOW_CTX_DAG_RUN_ID='manual__2024-02-13T01:02:49.486647+00:00'
[2024-02-13T10:02:54.275+0900] {taskinstance.py:1824} ERROR - Task failed with exception
Traceback (most recent call last):
  File "/home/shan/anaconda3/envs/airflow_env/lib/python3.7/site-packages/airflow/operators/python.py", line 181, in execute
    return_value = self.execute_callable()
  File "/home/shan/anaconda3/envs/airflow_env/lib/python3.7/site-packages/airflow/operators/python.py", line 198, in execute_callable
    return self.python_callable(*self.op_args, **self.op_kwargs)
  File "/home/shan/airflow/dags/naver_search_pipeline.py", line 19, in print_today
    print(datetime.datetime.now())
AttributeError: type object 'datetime.datetime' has no attribute 'datetime'
[2024-02-13T10:02:54.277+0900] {taskinstance.py:1350} INFO - Marking task as FAILED. dag_id=naver-search-pipeline, task_id=task_print_today, execution_date=20240213T010249, start_date=20240213T010254, end_date=20240213T010254
[2024-02-13T10:02:54.285+0900] {standard_task_runner.py:109} ERROR - Failed to execute job 133 for task task_print_today (type object 'datetime.datetime' has no attribute 'datetime'; 273189)
[2024-02-13T10:02:54.314+0900] {local_task_job_runner.py:225} INFO - Task exited with return code 1
[2024-02-13T10:02:54.325+0900] {taskinstance.py:2653} INFO - 0 downstream tasks scheduled from follow-on schedule check
